Workbook

Sheet Tabelle1

Sheet CapacitySFN
B3: Capacity check
B5: Part number | I5: Creator
B6: Part designation | I6: Date
B7: Project | I7: Department
B8: Supplier | I8: GSIS - Nr.
B9: Location
B11: Station 1 | F11: Shifts/week | G11: 7.5 | I11: Station 5 | M11: Shifts/week | P11: Station 9 | T11: Shifts/week
B12: Process: | F12: Pcs. Weekly | G12: =IF(G13*G15*G16*G18=0,0,G11*G14*60*60/G13*G15*G16*G18)*G17 -> 2055.9 | I12: Process: | M12: Pcs. Weekly | N12: =IF(N13*N15*N16*N18=0,0,N11*N14*60*60/N13*N15*N16*N18)*N17 -> #DIV/0! | P12: Process: | T12: Pcs. Weekly | U12: =IF(U13*U15*U16*U18=0,0,U11*U14*60*60/U13*U15*U16*U18)*U17 -> #DIV/0!
B13: Mesa de corte | F13: Cycle time in sec. | G13: ='OEE CalculatorSFN'!E14 -> 300 | I13: xxx | M13: Cycle time in sec. | N13: ='OEE CalculatorSFN'!I14 -> 0 | P13: xxx | T13: Cycle time in sec. | U13: ='OEE CalculatorSFN'!M14 -> 0
F14: Hours per shift | G14: 8 | M14: Hours per shift | T14: Hours per shift
F15: OEE | G15: ='OEE CalculatorSFN'!E23 -> 0.84982639 | M15: OEE | N15: ='OEE CalculatorSFN'!I23 -> #DIV/0! | T15: OEE | U15: ='OEE CalculatorSFN'!M23 -> #DIV/0!
F16: Cavities | G16: ='OEE CalculatorSFN'!E15 -> 12 | M16: Cavities | N16: ='OEE CalculatorSFN'!I15 -> 0 | T16: Cavities | U16: ='OEE CalculatorSFN'!M15 -> 0
E17: Reservation for project | G17: 0.14 | L17: Reservation for project | S17: Reservation for project
F18: Machines | G18: 2 | M18: Machines | T18: Machines
B20: Station 2 | F20: Shifts/week | I20: Station 6 | M20: Shifts/week | P20: Station 10 | T20: Shifts/week
B21: Process: | F21: Pcs. Weekly | G21: =IF(G22*G24*G25*G27=0,0,G20*G23*60*60/G22*G24*G25*G27)*G26 -> #DIV/0! | I21: Process: | M21: Pcs. Weekly | N21: =IF(N22*N24*N25*N27=0,0,N20*N23*60*60/N22*N24*N25*N27)*N26 -> #DIV/0! | P21: Process: | T21: Pcs. Weekly | U21: =IF(U22*U24*U25*U27=0,0,U20*U23*60*60/U22*U24*U25*U27)*U26 -> #DIV/0!
B22: Costura | F22: Cycle time in sec. | G22: ='OEE CalculatorSFN'!F14 -> 0 | I22: xxx | M22: Cycle time in sec. | N22: ='OEE CalculatorSFN'!J14 -> 0 | P22: xxx | T22: Cycle time in sec. | U22: ='OEE CalculatorSFN'!N14 -> 0
F23: Hours per shift | M23: Hours per shift | T23: Hours per shift
F24: OEE | G24: ='OEE CalculatorSFN'!F23 -> #DIV/0! | M24: OEE | N24: ='OEE CalculatorSFN'!J23 -> #DIV/0! | T24: OEE | U24: ='OEE CalculatorSFN'!N23 -> #DIV/0!
F25: Cavities | G25: ='OEE CalculatorSFN'!F15 -> 0 | M25: Cavities | N25: ='OEE CalculatorSFN'!J15 -> 0 | T25: Cavities | U25: ='OEE CalculatorSFN'!N15 -> 0
E26: Reservation for project | L26: Reservation for project | S26: Reservation for project
F27: Machines | M27: Machines | T27: Machines
B29: Station 3 | F29: Shifts/week | I29: Station 7 | M29: Shifts/week | P29: Station 11 | T29: Shifts/week
B30: Process: | F30: Pcs. Weekly | G30: =IF(G31*G33*G34*G36=0,0,G29*G32*60*60/G31*G33*G34*G36)*G35 -> #DIV/0! | I30: Process: | M30: Pcs. Weekly | N30: =IF(N31*N33*N34*N36=0,0,N29*N32*60*60/N31*N33*N34*N36)*N35 -> #DIV/0! | P30: Process: | T30: Pcs. Weekly | U30: =IF(U31*U33*U34*U36=0,0,U29*U32*60*60/U31*U33*U34*U36)*U35 -> #DIV/0!
B31: Proceso PIP | F31: Cycle time in sec. | G31: ='OEE CalculatorSFN'!G14 -> 0 | I31: xxx | M31: Cycle time in sec. | N31: ='OEE CalculatorSFN'!K14 -> 0 | P31: xxx | T31: Cycle time in sec. | U31: ='OEE CalculatorSFN'!O14 -> 0
F32: Hours per shift | M32: Hours per shift | T32: Hours per shift
F33: OEE | G33: ='OEE CalculatorSFN'!G23 -> #DIV/0! | M33: OEE | N33: ='OEE CalculatorSFN'!K23 -> #DIV/0! | T33: OEE | U33: ='OEE CalculatorSFN'!O23 -> #DIV/0!
F34: Cavities | G34: ='OEE CalculatorSFN'!G15 -> 0 | M34: Cavities | N34: ='OEE CalculatorSFN'!K15 -> 0 | T34: Cavities | U34: ='OEE CalculatorSFN'!O15 -> 0
E35: Reservation for project | L35: Reservation for project | S35: Reservation for project
F36: Machines | M36: Machines | T36: Machines
B38: Station 4 | F38: Shifts/week | I38: Station 8 | M38: Shifts/week | P38: Station 12 | T38: Shifts/week
B39: Process: | F39: Pcs. Weekly | G39: =IF(G40*G42*G43*G45=0,0,G38*G41*60*60/G40*G42*G43*G45)*G44 -> #DIV/0! | I39: Process: | M39: Pcs. Weekly | N39: =IF(N40*N42*N43*N45=0,0,N38*N41*60*60/N40*N42*N43*N45)*N44 -> #DIV/0! | P39: Process: | T39: Pcs. Weekly | U39: =IF(U40*U42*U43*U45=0,0,U38*U41*60*60/U40*U42*U43*U45)*U44 -> #DIV/0!
B40: xxx | F40: Cycle time in sec. | G40: ='OEE CalculatorSFN'!H14 -> 0 | I40: xxx | M40: Cycle time in sec. | N40: ='OEE CalculatorSFN'!L14 -> 0 | P40: xxx | T40: Cycle time in sec. | U40: ='OEE CalculatorSFN'!P14 -> 0
F41: Hours per shift | M41: Hours per shift | T41: Hours per shift
F42: OEE | G42: ='OEE CalculatorSFN'!H23 -> #DIV/0! | M42: OEE | N42: ='OEE CalculatorSFN'!L23 -> #DIV/0! | T42: OEE | U42: ='OEE CalculatorSFN'!P23 -> #DIV/0!
F43: Cavities | G43: ='OEE CalculatorSFN'!H15 -> 0 | M43: Cavities | N43: ='OEE CalculatorSFN'!L15 -> 0 | T43: Cavities | U43: ='OEE CalculatorSFN'!P15 -> 0
E44: Reservation for project | L44: Reservation for project | S44: Reservation for project
F45: Machines | M45: Machines | T45: Machines
C47: - input fields
C48: - result, protected formulas
...

Sheet OEE CalculatorSFN
C3: OEE-Calculator
D5: Part number | E5: =CapacitySFN!C5 -> 0 | K5: Creator | L5: =CapacitySFN!J5 -> 0
D6: Part designation | E6: =CapacitySFN!C6 -> 0 | K6: Date | L6: =CapacitySFN!J6 -> 0
D7: Project | E7: =CapacitySFN!C7 -> 0 | K7: Department | L7: =CapacitySFN!J7 -> 0
D8: Supplier | E8: =CapacitySFN!C8 -> 0 | K8: GSIS - Nr. | L8: =CapacitySFN!J8 -> 0
D9: Location | E9: =CapacitySFN!C9 -> 0
E11: Station 1 | F11: Station 2 | G11: Station 3 | H11: Station 4 | I11: Station 5 | J11: Station 6 | K11: Station 7 | L11: Station 8 | M11: Station 9 | N11: Station 10 | O11: Station 11 | P11: Station 12
B12: Variable | C12: Formel | E12: =CapacitySFN!B13 -> Mesa de corte | F12: =CapacitySFN!B22 -> Costura | G12: =CapacitySFN!B31 -> Proceso PIP | H12: =CapacitySFN!B40 -> xxx | I12: =CapacitySFN!I13 -> xxx | J12: =CapacitySFN!I22 -> xxx | K12: =CapacitySFN!I31 -> xxx | L12: =CapacitySFN!I40 -> xxx | M12: =CapacitySFN!P13 -> xxx | N12: =CapacitySFN!P22 -> xxx | O12: =CapacitySFN!P31 -> xxx | P12: =CapacitySFN!P40 -> xxx
B13: A | D13: Observation time (min) | E13: 480
B14: B | D14: Cycle time (sec) | E14: 300
B15: C | D15: Cavities (number) | E15: 12
B16: D | C16: A*60/B*C | D16: Target-unit by 100% OEE | E16: =E13*60/E14*E15 -> 1152 | F16: =F13*60/F14*F15 -> #DIV/0! | G16: =G13*60/G14*G15 -> #DIV/0! | H16: =H13*60/H14*H15 -> #DIV/0! | I16: =I13*60/I14*I15 -> #DIV/0! | J16: =J13*60/J14*J15 -> #DIV/0! | K16: =K13*60/K14*K15 -> #DIV/0! | L16: =L13*60/L14*L15 -> #DIV/0! | ... P16: =P13*60/P14*P15 -> #DIV/0!
B17: E | D17: recorded downtime during A (min) | E17: 30
B18: F | D18: total ok parts during A (psc) | E18: 979
B19: G | D19: total not ok parts during A (psc) | E19: 3
B20: H | C20: (A-E)/A | D20: Availability | E20: =(E13-E17)/E13 -> 0.9375 | F20: =(F13-F17)/F13 -> #DIV/0! | G20: =(G13-G17)/G13 -> #DIV/0! | H20: =(H13-H17)/H13 -> #DIV/0! | I20: =(I13-I17)/I13 -> #DIV/0! | J20: =(J13-J17)/J13 -> #DIV/0! | K20: =(K13-K17)/K13 -> #DIV/0! | L20: =(L13-L17)/L13 -> #DIV/0! | ... P20: =(P13-P17)/P13 -> #DIV/0!
B21: I | C21: (G+F)/((A-E)*60/B*C) | D21: Performance | E21: =(E19+E18)/((E13-E17)*60/E14*E15) -> 0.90925926 | F21: =(F19+F18)/((F13-F17)*60/F14*F15) -> #DIV/0! | G21: =(G19+G18)/((G13-G17)*60/G14*G15) -> #DIV/0! | H21: =(H19+H18)/((H13-H17)*60/H14*H15) -> #DIV/0! | I21: =(I19+I18)/((I13-I17)*60/I14*I15) -> #DIV/0! | J21: =(J19+J18)/((J13-J17)*60/J14*J15) -> #DIV/0! | K21: =(K19+K18)/((K13-K17)*60/K14*K15) -> #DIV/0! | L21: =(L19+L18)/((L13-L17)*60/L14*L15) -> #DIV/0! | ... P21: =(P19+P18)/((P13-P17)*60/P14*P15) -> #DIV/0!
B22: J | C22: F/(F+G) | D22: Quality | E22: =E18/(E18+E19) -> 0.99694501 | F22: =F18/(F18+F19) -> #DIV/0! | G22: =G18/(G18+G19) -> #DIV/0! | H22: =H18/(H18+H19) -> #DIV/0! | I22: =I18/(I18+I19) -> #DIV/0! | J22: =J18/(J18+J19) -> #DIV/0! | K22: =K18/(K18+K19) -> #DIV/0! | L22: =L18/(L18+L19) -> #DIV/0! | ... P22: =P18/(P18+P19) -> #DIV/0!
B23: K | C23: H*I*J | D23: OEE | E23: =E20*E21*E22 -> 0.84982639 | F23: =F20*F21*F22 -> #DIV/0! | G23: =G20*G21*G22 -> #DIV/0! | H23: =H20*H21*H22 -> #DIV/0! | I23: =I20*I21*I22 -> #DIV/0! | J23: =J20*J21*J22 -> #DIV/0! | K23: =K20*K21*K22 -> #DIV/0! | L23: =L20*L21*L22 -> #DIV/0! | ... P23: =P20*P21*P22 -> #DIV/0!
E25: XXX | F25: - input fields
B26: created: R. Härtel K-BN-KA/1 Tel. Nr.: 05361-9-45487

Sheet DiagramSFN
B3: Diagram total-capacity individual stations
B5: Max. - demand VW Group | F5: =F7*1.15 -> 2035.5 | G5: psc/week | J5: Creator | K5: =CapacitySFN!J5 -> 0
J6: Date | K6: =CapacitySFN!J6 -> 0
B7: Normal - demand VW Group | F7: 1770 | G7: psc/week | J7: Department | K7: =CapacitySFN!J7 -> 0
J8: GSIS - Nr. | K8: =CapacitySFN!J8 -> 0
H43: - input fields

Sheet Observaciones
B11: Station 1 | F11: Schichten/Woche: | G11: 15
B12: Prozess: | F12: Stck. wöchentlich: | G12: 2629.575
B13: KM 4000T Componente: Rear spoiler | F13: Zykluszeit in sec: | G13: 60
F14: Arbeitszeit in Std/Schicht | G14: 7.75
F15: OEE | G15: 0.8
F16: Kavitäten: | G16: 1
E17: Reservierung für o.g. Projekt | G17: 0.195
F18: Maschinen: | G18: 1

Sheet Protocolo_SFN1
B2: Protocolo de Aceptación
C4: Serienfähigkeitsnachweis SFN1
C6: Fecha de realización: | D6: =CapacitySFN!J6 -> 0 | E6: Clave de pieza: | F6: =CapacitySFN!C5 -> 0 | G6: Proyecto: | H6: =CapacitySFN!C7 -> 0
C7: Familia de piezas: | D7: =CapacitySFN!C6 -> 0
C8: Proveedor: | D8: =CapacitySFN!C8 -> 0 | E8: Lugar de fabricación: | F8: =CapacitySFN!C9 -> 0 | G8: DUNS: | H8: xxxx
C10: Resultado global*
C12: Rojo* | D12: No se cumplen los requerimientos acordados con el cliente. Está en peligro el lanzamiento del proyecto. No se concede la liberación de serie. Es necesario repetir SFN (1).
C13: Amarillo* | D13: No se cumplen completamente los requerimientos del cliente. Suministro posible con reservas en un determinado período o volumen segun peticiones de entrega de serie. Requiere repetición de SFN (1)
C14: Verde* | D14: Se cumplen completamente los requerimientos acordados con el cliente en cuanto a capacidad y calidad.
C15: *) El color del semáforo se define manualmente. Este resultado global se define en base a los resultados de la capacidad y de la lista de chequeo.
D16: Es necesario repetir la prueba de producción | G16: Fecha:
D17: Repetición a realizar | E17: por el proveedor en responsabilidad propia | G17: junto con el cliente
C18: X | D18: Con la prueba de producción se ha evaluado la cadena de procesos en base a la Lista de Chequeo SFN (Anexo)
C19: Resumen de cada uno de los resultados de la evaluación de la capacidad y del proceso:
C20: Cantidad de piezas OK/semana: | D20: =D72 -> #DIV/0! | E20: Cantidad de piezas OK/semana + 15% flexibilidad: | F20: =F72 -> #DIV/0! | G20: Resultado de la "Lista de chequeo SFN" (Evaluación proceso): | H20: =#REF! -> #REF!
C22: Resumen para la Dirección
C25: Problemas detectados
C27: Problema: | E27: Medida: | G27: Responsable: | H27: Plazo:
C34: Unidades de fabricación nominadas (capacidad)
C36: Unidades nominadas: unidades de fabr./año | D36: =D37*48 -> 55968 | E36: + 15% Flexibilität: unidades/año | F36: =D36*1.15 -> 64363.2 | G36: Nomination Agreement (NA) del:* | H36: ??
C37: Unidades nominadas: uds de fabr./semana* | D37: 1166 | E37: + 15% Flexibilidad: unidades/semana | F37: =F36/48 -> 1340.9 | G37: Volumen máx. p.a. seg. NA necesario a partir de: (año de volumen máximo)* | H37: ??
C38: Unidades a comprobar seg. Ficha Commitment de Piezas Nuevas: * | D38: 280 | E38: Acordado el:* | F38: KW31/20
C46: Capacidad planificada en el cuello de botella | G46: INYECCION 800TN - Molde de 1+1 cavidad
C48: Capacidad total para el Grupo Volkswagen:* | D48: 1 | E48: Capacidad total para la familia de piezas (pieza):* | F48: 0.2 | G48: OEE | H48: 0.85
C49: Número de líneas de produccion paralelas o moldes/htas.:* | D49: 1 | E49: Tiempo de trabajo/turno: Minutos* | F49: 450 | G49: Capacidad exigida en el proyecto está disponible (+ 15% flexibilidad)* | H49: X
C50: Tiempo de ciclo planificado/pieza Minutos/Pieza* | D50: 1.083 | E50: Rechazos previstos (a causa del proceso, en %):* | F50: 0.02 | G50: Capacidad exigida en el proyecto disponible a partir de:* | H50: KW14/21
C51: Turnos/semana:* | D51: 15 | E51: Cantidad máxima de turnos:* | F51: 17 | G51: Capacidad exigida en el año de mayor volumen seg. NA está disponible (+ 15% flexibilidad)** | H51: X
C52: Unidades planificadas /semana: Base: turnos/semana | D52: =D49*F49/D50*D51*H48*F48*D48*(100%-F50) -> 1038.3657 | E52: Máximas unidades planificadas/semana: Base: cantidad máxima de turnos | F52: =D49*F49/D50*F51*H48*F48*D48*(100%-F50) -> 1176.8144 | G52: Capacidad para año de mayor volumen seg. NA planificada a partir de:** | H52: ??
C53: Comentario / aseguramiento de la flexibilidad: | D53: Con el equipo actual se cubre la capacidad incluyendo la flexibilidad.
C56: Capacidad comprobada en el cuello de botella | G56: INYECCION 800TN - Molde de 1+1 cavidad
C58: Cantidad de líneas de fabricación / htas. disponibles durante la aceptación:* | D58: 1 | E58: Duración de la prueba de producción:* Minutos | F58: 0 | G58: Cantidad de piezas fabricadas:* | H58: 0
C59: Cantidad de piezas OK ("producción directa"):* | D59: =H58-F59-H59 -> 0 | E59: Cantidad de piezas para retrabajo:* | F59: 0 | G59: Entre ellas piezas rechazadas:* | H59: 0
C60: Cantidad de piezas OK: (Producción directa + retrabajadas) | D60: =D59+F59 -> 0 | E60: Cuota de producción directa: | F60: =D59/H58 -> #DIV/0! | G60: Cuota de rechazos: | H60: =H59/H58 -> #DIV/0!
C62: Resultado de la evaluación de la capacidad (capacidad real)
C64: Cálculo incluyendo la disponibildad de las instalaciones (Producción < 1 Turno)
C66: Anzahl vorhandene Fertigungslinien/ Serienwerkzeuge für die Prozessabnahme:* | E66: Menge i.O.-Teile/ Woche: | F66: =IF($H$64="x",((($D$59/$D$58)*$D$49)/$F$58*$F$49*$D$51*$D$48*$F$48*$H$48),"n.b.") -> n.b. | G66: Menge i.O.-Teile/Woche inkl 15 % Flexibilität: | H66: =IF($H$64="x",((($D$59/$D$58)*$D$49)/$F$58*$F$49*$F$51*$D$48*$F$48*$H$48),"n.b.") -> n.b.
C67: Aclaración sobre el cálculo de la catidad de piezas OK/semana: Cantidad piezas OK ("producción directa") / Duración de la prueba de aceptacion x Minutos/turno x Cantidad de turnos planeados x Capacidad todal para el grupo VW x Capacidad todal para la pieza x Disponibilidad de las intalación planificada. Activar el cálculo a través de una "X" en el cuadro superior derecho.
C68: Cálculo sin incluir la disponibildad de las instalaciones (Producción ≥ 1 Turno) | H68: X
C70: Anzahl vorhandene Fertigungslinien/ Serienwerkzeuge für den Leistungstest:* | E70: Menge i.O.-Teile/ Woche: | F70: =IF($H$68="x",((($D$59/$D$58)*$D$49)/$F$58*$F$49*$D$51*$D$48*$F$48),"n.b.") -> #DIV/0! | G70: Menge i.O.-Teile/Woche inkl 15 % Flexibilität: | H70: =IF($H$68="x",((($D$59/$D$58)*$D$49)/$F$58*$F$49*$F$51*$D$48*$F$48),"n.b.") -> #DIV/0!
C71: Aclaración sobre el cálculo de la catidad de piezas OK/semana: Cantidad piezas OK ("producción directa") / Duración de la prueba de aceptacion x Minutos/turno x Cantidad de turnos planeados x Capacidad todal para el grupo VW x Capacidad todal para la pieza. Activar el cálculo a través de una "X" en el cuadro superior derecho.
...

Sheet Acc. certificate PCA1 pre-check
C2: Acceptance certificate
C4: Production Capability Analysis PCA1 (preliminary check)
C6: Date: | D6: 43584 | E6: Part number: | F6: 11B/C 941 005 / 006 | G6: Project: | H6: VW316/6 EU_B
C7: Component designation: | D7: Headlights, basic
C8: Supplier: | D8: Supplier 1 | E8: Production facility: | F8: Wolfsburg | G8: DUNS: | H8: 36408695
C10: Overall result*
C12: Red* | D12: Agreed customer requirements were not met. The project start-up is at risk. Production approval will not be granted. The acceptance will need to be repeated.
C13: Yellow* | D13: Agreed customer requirements were not met in full. Delivery can occur for a specific period or quantity in accordance with production delivery call-offs, subject to constraints.
C14: *) Colour of traffic light set manually. Overall result is comprised of the individual result for Capacity and the result of the Checklist.
C15: X | D15: The acceptance will need to be repeated | G15: Due date: | H15: 43617
D16: The acceptance will be performed | E16: at the supplier’s own responsibility | G16: together with the customer
C17: X | D17: The process chain was assessed using the PCA checklist (annex) with the acceptance
C18: Summary of the individual results from the capacity and process assessment
C19: Number of OK parts/week: | D19: =D66 -> 14032.012 | E19: Number of OK parts/week incl. 15% flexibility: | F19: =F66 -> 15902.947 | G19: Result from the PCA checklist (process assessment): | H19: =IF(#REF!=0,"n.r.",#REF!) -> #REF!
C21: Management summary
C22: Summary of the overall status and short explanation of the result. Also record any stoppages (downtime) at the plants. The cycle time/length of cycle must be recorded explicitly.
C24: Problems identified
C26: Problem: | E26: Measure: | G26: Responsible: | H26: Due date:
C27: First problem description for the acceptance certificate PCA1 | E27: Measure for the first problem | G27: Name Surname | H27: 43800
C28: Second problem description for the acceptance certificate PCA1 | E28: Measure for the second problem | G28: Name Surname | H28: 43800
C33: Nominated quantity (capacity) as per Nomination Agreement
C35: Nominated quantity: Annual quantity | D35: =D36*48 -> 399984 | E35: Incl. 15% flexibility: Annual quantity | F35: =D35*1.15 -> 459981.6 | G35: Nomination agreement (NA) dated:* | H35: 42848
C36: Nominated quantity: Pieces/week* | D36: 8333 | E36: Incl. 15% flexibility: pieces/week | F36: =F35/48 -> 9582.95 | G36: Max. planned volume per year as per NA necessary from: (maximum year)* | H36: 44013
C37: Acceptance quantity as per New Parts Commitment sheet:* | D37: 950 | E37: Agreed on:* | F37: 43101
C45: Planned capacity in the sequence of operations that decides capacity: | G45: Assembly ASSY
C47: Entire Group capacity for the Volkswagen Group:* | D47: 1 | E47: Group capacity for parts family (component):* | F47: 0.75 | G47: Planned plant availability incl. setup times* | H47: 0.85
C48: Number of parallel production lines or tools:* | D48: 1 | E48: Working hours/shift: Minutes* | F48: 460 | G48: Peak production capacity for project has been set up (incl. 15% flexibility)* | H48: X
C49: Planned cycle time/component:* Minutes/component | D49: 0.5 | E49: Planned reject rate: (process related in %):* | F49: 0.02 | G49: Peak production quantity for project available from:* | H49: 43831
C50: Shifts/week:* | D50: 15 | E50: Maximum shifts:* | F50: 17 | G50: Capacity for highest-volume year as per NA has been set up (incl. 15% flexibility)** | H50: X
C51: Planned quantity/week: Basis: shifts/week | D51: =D48*F48/D49*D50*H47*F47*D47*(100%-F49) -> 8621.55 | E51: Planned maximum quantity/week: Basis: max. shifts | F51: =D48*F48/D49*F50*H47*F47*D47*(100%-F49) -> 9771.09 | G51: Capacity for highest-volume year as per NA has been set up from:** | H51: 43831
C52: Note/ensuring flexibility: | D52: Measures to ensure flexibility
C55: Quantity identified for the sequence of operations that defines capacity: | G55: Assembly ASSY
C57: Number of production lines/ production tools available for the acceptance:* | D57: 1 | E57: Duration of acceptance:* Minutes | F57: 300 | G57: Number of parts produced:* | H57: 975
C58: Number of OK parts (first pass):* | D58: =H57-F58-H58 -> 957 | E58: Number of reworked parts:* | F58: 8 | G58: Number of these that are reject parts:* | H58: 10
C59: Number of OK parts: (first pass + rework) | D59: =D58+F58 -> 965 | E59: First pass rate: | F59: =D58/H57 -> 0.98153846 | G59: Reject rate: | H59: =H58/H57 -> 0.01025641
C61: Result of capacity assessment (actual capacity)
C63: Berechnung mit Berücksichtigung der Anlagenverfügbarkeit (Abnahmevolumen < 1 Schicht) | H63: X | J63: ausblenden
C64: Anzahl vorhandene Fertigungslinien/ Serienwerkzeuge für die Prozessabnahme:* | E64: Menge i.O.-Teile/ Woche: | F64: =IF($H$63="x",((($D$58/$D$57)*$D$48)/$F$57*$F$48*$D$50*$D$47*$F$47*$H$47),"n.b.") -> 14032.012 | G64: Menge i.O.-Teile/Woche inkl 15 % Flexibilität: | H64: =IF($H$63="x",(($D$58/$D$57*$D$48)/$F$57*$F$48*$F$50*$D$47*$F$47*$H$47),"n.b.") -> 15902.947 | J64: ausblenden
C65: Erläuterung zur Berechnung der Menge i.O.-Teile/Woche: Anzahl i.O.-Teile (Direktläufer) / Dauer der Abnahme x Minuten/Schicht x Anzahl der geplanten Schichten x Gesamtgruppenkapazität x Gruppenkapazität für Teilefamilie x Geplante Anlagenverfügbarkeit. | J65: ausblenden
C66: Number of OK parts/week: | D66: =IF(H64="n.b.",#REF!,F64) -> 14032.012 | E66: Number of OK parts/week incl. 15% flexibility: | F66: =IF(H64="n.b.",#REF!,H64) -> 15902.947 | G66: Nominated quantity: Pieces/week | H66: =D36 -> 8333
...

Sheet Acceptance certificate_PCA2_3
C2: Acceptance certificate
C4: X | D4: Production Capability Analysis PCA2 | G4: Production Capability Analysis PCA3
C6: Date: | D6: 43800 | E6: Part number: | F6: ='Acc. certificate PCA1 pre-check'!F6 -> 11B/C 941 005 / 006 | G6: Project: | H6: ='Acc. certificate PCA1 pre-check'!H6 -> VW316/6 EU_B
C7: Component designation: | D7: ='Acc. certificate PCA1 pre-check'!D7:F7 -> Headlights, basic
C8: Supplier: | D8: ='Acc. certificate PCA1 pre-check'!D8 -> Supplier 1 | E8: Production facility: | F8: ='Acc. certificate PCA1 pre-check'!F8 -> Wolfsburg | G8: DUNS: | H8: ='Acc. certificate PCA1 pre-check'!H8 -> 36408695
C10: Overall result*
C12: Red* | D12: Agreed customer requirements were not met. The project start-up is at risk. Production capability will not be granted. The acceptance will need to be repeated.
C13: Yellow* | D13: Agreed customer requirements were not met in full. Delivery can occur for a specific period or quantity in accordance with production delivery call-offs, subject to constraints. This must be repeated.
C14: Green* | D14: The agreed customer requirements in relation to capacity and quality were satisfied in full.
C15: *) Colour of traffic light set manually. Overall result is comprised of the individual result for Capacity and the result of the PCA checklist.
C16: x | D16: The acceptance will need to be repeated | G16: Due date: | H16: 43497
D17: The acceptance will be performed | E17: at the supplier’s own responsibility | G17: together with the customer
C18: X | D18: The proof of production capability was assessed using the PCA checklist (annex) with the acceptance
C19: Summary of the individual results of the proof of production capability
C20: Number of OK parts/week: | D20: =D72 -> 13365 | E20: Number of OK parts/week incl. 15% flexibility: | F20: =F72 -> 15147 | G20: Result from the PCA checklist (capability assessment): | H20: =#REF! -> #REF!
C22: Management summary
C23: Summary of the overall status and short explanation of the result. Also record stoppages (downtime) at the plants. The cycle time/length of cycle must be recorded explicitly.
C25: Problems identified
C27: Problem: | E27: Measure: | G27: Responsible: | H27: Due date:
C28: First problem description for the acceptance certificate PCA2 | E28: Measure for the first problem | G28: Name Surname | H28: 43800
C29: Second problem description for the acceptance certificate PCA2 | E29: Measure for the second problem | G29: Name Surname | H29: 43800
C34: Nominated quantity (capacity) as per Nomination Agreement
C36: Nominated quantity: Annual quantity | D36: =D37*48 -> 399984 | E36: incl. 15% flexibility: Annual quantity | F36: =D36*1.15 -> 459981.6 | G36: Nomination agreement (NA) dated:* | H36: 42848
C37: Nominated quantity: Pieces/week* | D37: 8333 | E37: incl. 15% flexibility: pieces/week | F37: =F36/48 -> 9582.95 | G37: Max. planned volume per year as per NA necessary from: (maximum year)* | H37: 44013
C38: Acceptance quantity as per New Parts Commitment sheet:* | D38: 200 | E38: Agreed on:* | F38: 43466
C46: Planned capacity in the sequence of operations that decides capacity: | G46: Assembly ASSY
C48: Entire Group capacity for the Volkswagen Group:* | D48: 1 | E48: Group capacity for parts family (component):* | F48: 0.75 | G48: Planned plant availability incl. setup times* | H48: 0.85
C49: Number of parallel production lines or tools:* | D49: 1 | E49: Working hours/shift: Minutes* | F49: 480 | G49: Peak production capacity for project has been set up (incl. 15% flexibility)* | H49: X
C50: Planned cycle time/component:* Minutes/component | D50: 0.5 | E50: Planned reject rate: (process related in %):* | F50: 0.02 | G50: Peak production quantity for project available from:* | H50: 43831
C51: Shifts/week:* | D51: 15 | E51: Maximum shifts:* | F51: 17 | G51: Capacity for highest-volume year as per NA has been set up (incl. 15% flexibility)** | H51: X
C52: Planned quantity/week: Basis: shifts/week | D52: =D49*F49/D50*D51*H48*F48*D48*(100%-F50) -> 8996.4 | E52: Planned maximum quantity/week: Basis: max. shifts | F52: =D49*F49/D50*F51*H48*F48*D48*(100%-F50) -> 10195.92 | G52: Capacity for highest-volume year as per NA has been set up from:** | H52: 43831
C53: Note/ensuring flexibility: | D53: Measures to ensure flexibility
C56: Quantity identified for the sequence of operations that defines capacity: | G56: Assembly ASSY
C58: Number of production lines/ production tools available for the acceptance:* | D58: 1 | E58: Duration of acceptance:* Minutes | F58: 480 | G58: Number of parts produced:* | H58: 1200
C59: Number of OK parts (first pass):* | D59: =H58-F59-H59 -> 1188 | E59: Number of reworked parts:* | F59: 0 | G59: Number of these that are reject parts:* | H59: 12
C60: Number of OK parts: (first pass + rework) | D60: =D59+F59 -> 1188 | E60: First pass rate: | F60: =D59/H58 -> 0.99 | G60: Reject rate: | H60: =H59/H58 -> 0.01
C62: Result of capacity assessment (actual capacity)
C64: Calculation factors in plant availability (acceptance volume < 1 shift)
C66: Number of production lines/ production tools available for the process acceptance:* | E66: Number of OK parts/week: | F66: =IF($H$64="x",((($D$59/$D$58)*$D$49)/$F$58*$F$49*$D$51*$D$48*$F$48*$H$48),"n.b.") -> n.b. | G66: Number of OK parts/week incl. 15% flexibility: | H66: =IF($H$64="x",((($D$59/$D$58)*$D$49)/$F$58*$F$49*$F$51*$D$48*$F$48*$H$48),"n.b.") -> n.b.
C67: Explanation of the calculation of the quantity of OK parts/week: Number of OK parts (first pass)/duration of the acceptance × minutes/shift × number of planned shifts × overall Group capacity × Group capacity for parts family × planned plant availability. Activate calculation in the top row using X.
...
